Workbook

Sheet Financial Projection
A2: Prayat (ScamSim) — 3-Year Financial Projection
A3: Currency: USD. Two B2C tiers — Standard $1.50/month and Premium $2.50/month — plus a school licence. Blue text on yellow = editable assumption; black = formula; green = link to another sheet.
A5: Section | B5: Assumption | C5: Formula / reference | D5: Year 1 | E5: Year 2 | F5: Year 3
A6: Pricing
B7: Standard subscription fee (per month) | C7: Tier 1 — individual, all modes, score tracking | D7: 1.5 | E7: 1.5 | F7: 1.5
B8: Premium subscription fee (per month) | C8: Tier 2 — family plan (up to 4), parent dashboard, reports | D8: 2.5 | E8: 2.5 | F8: 2.5
B9: School licence fee (per student per month) | C9: B2B — per-student licence, billed to the school | D9: 1.5 | E9: 1.5 | F9: 1.5
A11: Standard tier — customers
B12: Beginning Standard subscribers | C12: Year 1 input; later years link to prior ending | D12: =0 | E12: =D17 | F12: =E17
B13: New Standard subscribers | C13: Acquisition assumption — parents, students, young adults (team estimate) | D13: 800 | E13: 2500 | F13: 6000
B14: Monthly churn — Standard | C14: Subscribers lost / subscribers at start of month (team estimate, price-sensitive consumer app) | D14: 0.04 | E14: 0.03 | F14: 0.025
B15: Annual churn — Standard | C15: 1 - (1 - monthly churn)^12 | D15: =1-(1-D14)^12 | E15: =1-(1-E14)^12 | F15: =1-(1-F14)^12
B16: Standard subscribers lost | C16: (Beginning + 50% of new) x annual churn | D16: =(D12+D13*50%)*D15 | E16: =(E12+E13*50%)*E15 | F16: =(F12+F13*50%)*F15
B17: Ending Standard subscribers | C17: Beginning + new - lost | D17: =D12+D13-D16 | E17: =E12+E13-E16 | F17: =F12+F13-F16
B18: Average Standard subscribers | C18: (Beginning + ending) / 2 | D18: =(D12+D17)/2 | E18: =(E12+E17)/2 | F18: =(F12+F17)/2
A20: Premium tier — customers
B21: Beginning Premium subscribers | C21: Year 1 input; later years link to prior ending | D21: =0 | E21: =D26 | F21: =E26
B22: New Premium subscribers | C22: Acquisition assumption — families, adult children buying for parents (team estimate) | D22: 200 | E22: 700 | F22: 2000
B23: Monthly churn — Premium | C23: Family plans churn less than individuals (team estimate) | D23: 0.03 | E23: 0.025 | F23: 0.02
B24: Annual churn — Premium | C24: 1 - (1 - monthly churn)^12 | D24: =1-(1-D23)^12 | E24: =1-(1-E23)^12 | F24: =1-(1-F23)^12
B25: Premium subscribers lost | C25: (Beginning + 50% of new) x annual churn | D25: =(D21+D22*50%)*D24 | E25: =(E21+E22*50%)*E24 | F25: =(F21+F22*50%)*F24
B26: Ending Premium subscribers | C26: Beginning + new - lost | D26: =D21+D22-D25 | E26: =E21+E22-E25 | F26: =F21+F22-F25
B27: Average Premium subscribers | C27: (Beginning + ending) / 2 | D27: =(D21+D26)/2 | E27: =(E21+E26)/2 | F27: =(F21+F26)/2
A29: School licence — students
B30: Licensed students (average over the year) | C30: Pilot 1 school in Y1 (deck draft), then 4 and 10 schools (team estimate) | D30: 200 | E30: 800 | F30: 2000
A32: All paying users
B33: Ending B2C subscribers (Standard + Premium) | C33: Ending Standard + ending Premium | D33: =D17+D26 | E33: =E17+E26 | F33: =F17+F26
B34: Average paying users (B2C + school) | C34: Average Standard + average Premium + licensed students | D34: =D18+D27+D30 | E34: =E18+E27+E30 | F34: =F18+F27+F30
B35: Ending MRR | C35: Ending Standard x $1.50 + ending Premium x $2.50 + students x school fee | D35: =D17*D7+D26*D8+D30*D9 | E35: =E17*E7+E26*E8+E30*E9 | F35: =F17*F7+F26*F8+F30*F9
B36: Ending ARR | C36: MRR x 12 | D36: =D35*12 | E36: =E35*12 | F36: =F35*12
A38: Sales Revenue
B39: Standard revenue | C39: Average Standard subscribers x $1.50 x 12 | D39: =D18*D7*12 | E39: =E18*E7*12 | F39: =F18*F7*12
B40: Premium revenue | C40: Average Premium subscribers x $2.50 x 12 | D40: =D27*D8*12 | E40: =E27*E8*12 | F40: =F27*F8*12
B41: School licence revenue | C41: Licensed students x school fee x 12 | D41: =D30*D9*12 | E41: =E30*E9*12 | F41: =F30*F9*12
B42: Total recognized revenue | C42: Standard + Premium + school | D42: =SUM(D39:D41) | E42: =SUM(E39:E41) | F42: =SUM(F39:F41)
B43: Revenue growth | C43: Current year / prior year - 1 | D43: ="" | E43: =E42/D42-1 | F43: =F42/E42-1
B44: Blended ARPU per user per month | C44: Total revenue / average paying users / 12 | D44: =IF(D34=0,0,D42/D34/12) | E44: =IF(E34=0,0,E42/E34/12) | F44: =IF(F34=0,0,F42/F34/12)
B45: Premium share of B2C subscribers | C45: Ending Premium / ending B2C | D45: =IF(D33=0,0,D26/D33) | E45: =IF(E33=0,0,E26/E33) | F45: =IF(F33=0,0,F26/F33)
A47: COGS / Service Delivery
B48: Hosting cost per user/month | C48: Render + SQLite today; scales down per user (team estimate) | D48: 0.04 | E48: 0.03 | F48: 0.025
...

Sheet Summary
A1: Prayat — 3-year summary
A2: Every cell links to the Financial Projection sheet (green). Edit assumptions there, not here.
A4: Metric | B4: Year 1 | C4: Year 2 | D4: Year 3
A5: Ending B2C subscribers | B5: ='Financial Projection'!D33 | C5: ='Financial Projection'!E33 | D5: ='Financial Projection'!F33
A6: Licensed students | B6: ='Financial Projection'!D30 | C6: ='Financial Projection'!E30 | D6: ='Financial Projection'!F30
A7: Ending MRR | B7: ='Financial Projection'!D35 | C7: ='Financial Projection'!E35 | D7: ='Financial Projection'!F35
A8: Total revenue | B8: ='Financial Projection'!D42 | C8: ='Financial Projection'!E42 | D8: ='Financial Projection'!F42
A9: Revenue growth | B9: ='Financial Projection'!D43 | C9: ='Financial Projection'!E43 | D9: ='Financial Projection'!F43
A10: Gross margin | B10: ='Financial Projection'!D57 | C10: ='Financial Projection'!E57 | D10: ='Financial Projection'!F57
A11: Sales and marketing | B11: ='Financial Projection'!D62 | C11: ='Financial Projection'!E62 | D11: ='Financial Projection'!F62
A12: Operating expenses | B12: ='Financial Projection'!D72 | C12: ='Financial Projection'!E72 | D12: ='Financial Projection'!F72
A13: EBITDA | B13: ='Financial Projection'!D79 | C13: ='Financial Projection'!E79 | D13: ='Financial Projection'!F79
A14: Net profit | B14: ='Financial Projection'!D84 | C14: ='Financial Projection'!E84 | D14: ='Financial Projection'!F84
A15: Ending cash | B15: ='Financial Projection'!D98 | C15: ='Financial Projection'!E98 | D15: ='Financial Projection'!F98
A16: Break-even paying users | B16: ='Financial Projection'!D90 | C16: ='Financial Projection'!E90 | D16: ='Financial Projection'!F90
A17: CAC | B17: ='Financial Projection'!D63 | C17: ='Financial Projection'!E63 | D17: ='Financial Projection'!F63
A18: LTV:CAC — Standard | B18: ='Financial Projection'!D107 | C18: ='Financial Projection'!E107 | D18: ='Financial Projection'!F107
A19: LTV:CAC — Premium | B19: ='Financial Projection'!D108 | C19: ='Financial Projection'!E108 | D19: ='Financial Projection'!F108
A21: Year 3 / Year 1 revenue | B21: =IF(B8=0,0,D8/B8)
A22: Average annual revenue growth | B22: =AVERAGE(C9:D9)
